[2023-10-15T10:33:40.400-0300] {taskinstance.py:1103} INFO - Dependencies all met for dep_context=non-requeueable deps ti=<TaskInstance: Executando-notebook-etl.Extraindo-conversoes scheduled__2023-08-28T09:00:00+00:00 [queued]>
[2023-10-15T10:33:40.414-0300] {taskinstance.py:1103} INFO - Dependencies all met for dep_context=requeueable deps ti=<TaskInstance: Executando-notebook-etl.Extraindo-conversoes scheduled__2023-08-28T09:00:00+00:00 [queued]>
[2023-10-15T10:33:40.414-0300] {taskinstance.py:1308} INFO - Starting attempt 1 of 1
[2023-10-15T10:33:40.446-0300] {taskinstance.py:1327} INFO - Executing <Task(DatabricksRunNowOperator): Extraindo-conversoes> on 2023-08-28 09:00:00+00:00
[2023-10-15T10:33:40.449-0300] {standard_task_runner.py:57} INFO - Started process 15824 to run task
[2023-10-15T10:33:40.453-0300] {standard_task_runner.py:84} INFO - Running: ['airflow', 'tasks', 'run', 'Executando-notebook-etl', 'Extraindo-conversoes', 'scheduled__2023-08-28T09:00:00+00:00', '--job-id', '39', '--raw', '--subdir', 'DAGS_FOLDER/extraindo-taxas.py', '--cfg-path', '/tmp/tmp9qzjz3eq']
[2023-10-15T10:33:40.456-0300] {standard_task_runner.py:85} INFO - Job 39: Subtask Extraindo-conversoes
[2023-10-15T10:33:40.514-0300] {task_command.py:410} INFO - Running <TaskInstance: Executando-notebook-etl.Extraindo-conversoes scheduled__2023-08-28T09:00:00+00:00 [running]> on host DESKTOP-L4GJ4I7.
[2023-10-15T10:33:40.564-0300] {abstractoperator.py:593} ERROR - Exception rendering Jinja template for task 'Extraindo-conversoes', field 'json'. Template: {'job_id': '307543230213856', 'notebook_params': {'data_execucao': '{{data_interval_end.strftime("%Y-%m-%d)}}'}}
Traceback (most recent call last):
  File "/home/tinoco/airflow-databricks/curso_datAir/lib/python3.10/site-packages/airflow/models/abstractoperator.py", line 585, in _do_render_template_fields
    rendered_content = self.render_template(
  File "/home/tinoco/airflow-databricks/curso_datAir/lib/python3.10/site-packages/airflow/template/templater.py", line 168, in render_template
    return {k: self.render_template(v, context, jinja_env, oids) for k, v in value.items()}
  File "/home/tinoco/airflow-databricks/curso_datAir/lib/python3.10/site-packages/airflow/template/templater.py", line 168, in <dictcomp>
    return {k: self.render_template(v, context, jinja_env, oids) for k, v in value.items()}
  File "/home/tinoco/airflow-databricks/curso_datAir/lib/python3.10/site-packages/airflow/template/templater.py", line 168, in render_template
    return {k: self.render_template(v, context, jinja_env, oids) for k, v in value.items()}
  File "/home/tinoco/airflow-databricks/curso_datAir/lib/python3.10/site-packages/airflow/template/templater.py", line 168, in <dictcomp>
    return {k: self.render_template(v, context, jinja_env, oids) for k, v in value.items()}
  File "/home/tinoco/airflow-databricks/curso_datAir/lib/python3.10/site-packages/airflow/template/templater.py", line 155, in render_template
    template = jinja_env.from_string(value)
  File "/home/tinoco/airflow-databricks/curso_datAir/lib/python3.10/site-packages/jinja2/environment.py", line 1105, in from_string
    return cls.from_code(self, self.compile(source), gs, None)
  File "/home/tinoco/airflow-databricks/curso_datAir/lib/python3.10/site-packages/jinja2/environment.py", line 768, in compile
    self.handle_exception(source=source_hint)
  File "/home/tinoco/airflow-databricks/curso_datAir/lib/python3.10/site-packages/jinja2/environment.py", line 936, in handle_exception
    raise rewrite_traceback_stack(source=source)
  File "<unknown>", line 1, in template
jinja2.exceptions.TemplateSyntaxError: unexpected char '"' at 29
[2023-10-15T10:33:40.566-0300] {taskinstance.py:1824} ERROR - Task failed with exception
Traceback (most recent call last):
  File "/home/tinoco/airflow-databricks/curso_datAir/lib/python3.10/site-packages/airflow/models/taskinstance.py", line 1407, in _run_raw_task
    self._execute_task_with_callbacks(context, test_mode)
  File "/home/tinoco/airflow-databricks/curso_datAir/lib/python3.10/site-packages/airflow/models/taskinstance.py", line 1531, in _execute_task_with_callbacks
    task_orig = self.render_templates(context=context)
  File "/home/tinoco/airflow-databricks/curso_datAir/lib/python3.10/site-packages/airflow/models/taskinstance.py", line 2179, in render_templates
    original_task.render_template_fields(context)
  File "/home/tinoco/airflow-databricks/curso_datAir/lib/python3.10/site-packages/airflow/models/baseoperator.py", line 1254, in render_template_fields
    self._do_render_template_fields(self, self.template_fields, context, jinja_env, set())
  File "/home/tinoco/airflow-databricks/curso_datAir/lib/python3.10/site-packages/airflow/utils/session.py", line 76, in wrapper
    return func(*args, session=session, **kwargs)
  File "/home/tinoco/airflow-databricks/curso_datAir/lib/python3.10/site-packages/airflow/models/abstractoperator.py", line 585, in _do_render_template_fields
    rendered_content = self.render_template(
  File "/home/tinoco/airflow-databricks/curso_datAir/lib/python3.10/site-packages/airflow/template/templater.py", line 168, in render_template
    return {k: self.render_template(v, context, jinja_env, oids) for k, v in value.items()}
  File "/home/tinoco/airflow-databricks/curso_datAir/lib/python3.10/site-packages/airflow/template/templater.py", line 168, in <dictcomp>
    return {k: self.render_template(v, context, jinja_env, oids) for k, v in value.items()}
  File "/home/tinoco/airflow-databricks/curso_datAir/lib/python3.10/site-packages/airflow/template/templater.py", line 168, in render_template
    return {k: self.render_template(v, context, jinja_env, oids) for k, v in value.items()}
  File "/home/tinoco/airflow-databricks/curso_datAir/lib/python3.10/site-packages/airflow/template/templater.py", line 168, in <dictcomp>
    return {k: self.render_template(v, context, jinja_env, oids) for k, v in value.items()}
  File "/home/tinoco/airflow-databricks/curso_datAir/lib/python3.10/site-packages/airflow/template/templater.py", line 155, in render_template
    template = jinja_env.from_string(value)
  File "/home/tinoco/airflow-databricks/curso_datAir/lib/python3.10/site-packages/jinja2/environment.py", line 1105, in from_string
    return cls.from_code(self, self.compile(source), gs, None)
  File "/home/tinoco/airflow-databricks/curso_datAir/lib/python3.10/site-packages/jinja2/environment.py", line 768, in compile
    self.handle_exception(source=source_hint)
  File "/home/tinoco/airflow-databricks/curso_datAir/lib/python3.10/site-packages/jinja2/environment.py", line 936, in handle_exception
    raise rewrite_traceback_stack(source=source)
  File "<unknown>", line 1, in template
jinja2.exceptions.TemplateSyntaxError: unexpected char '"' at 29
[2023-10-15T10:33:40.572-0300] {taskinstance.py:1345} INFO - Marking task as FAILED. dag_id=Executando-notebook-etl, task_id=Extraindo-conversoes, execution_date=20230828T090000, start_date=20231015T133340, end_date=20231015T133340
[2023-10-15T10:33:40.605-0300] {standard_task_runner.py:104} ERROR - Failed to execute job 39 for task Extraindo-conversoes (unexpected char '"' at 29; 15824)
[2023-10-15T10:33:40.625-0300] {local_task_job_runner.py:225} INFO - Task exited with return code 1
[2023-10-15T10:33:40.637-0300] {taskinstance.py:2651} INFO - 0 downstream tasks scheduled from follow-on schedule check
