[2023-10-15T20:05:31.901-0300] {taskinstance.py:1103} INFO - Dependencies all met for dep_context=non-requeueable deps ti=<TaskInstance: Executando-notebook-etl.transformando_dados scheduled__2023-10-10T14:20:00+00:00 [queued]>
[2023-10-15T20:05:31.907-0300] {taskinstance.py:1103} INFO - Dependencies all met for dep_context=requeueable deps ti=<TaskInstance: Executando-notebook-etl.transformando_dados scheduled__2023-10-10T14:20:00+00:00 [queued]>
[2023-10-15T20:05:31.907-0300] {taskinstance.py:1308} INFO - Starting attempt 1 of 1
[2023-10-15T20:05:31.936-0300] {taskinstance.py:1327} INFO - Executing <Task(DatabricksRunNowOperator): transformando_dados> on 2023-10-10 14:20:00+00:00
[2023-10-15T20:05:31.940-0300] {standard_task_runner.py:57} INFO - Started process 17397 to run task
[2023-10-15T20:05:31.943-0300] {standard_task_runner.py:84} INFO - Running: ['airflow', 'tasks', 'run', 'Executando-notebook-etl', 'transformando_dados', 'scheduled__2023-10-10T14:20:00+00:00', '--job-id', '289', '--raw', '--subdir', 'DAGS_FOLDER/extraindo-taxas.py', '--cfg-path', '/tmp/tmpo02dpitd']
[2023-10-15T20:05:31.946-0300] {standard_task_runner.py:85} INFO - Job 289: Subtask transformando_dados
[2023-10-15T20:05:32.001-0300] {task_command.py:410} INFO - Running <TaskInstance: Executando-notebook-etl.transformando_dados scheduled__2023-10-10T14:20:00+00:00 [running]> on host DESKTOP-L4GJ4I7.
[2023-10-15T20:05:32.119-0300] {taskinstance.py:1545} INFO - Exporting env vars: AIRFLOW_CTX_DAG_OWNER='airflow' AIRFLOW_CTX_DAG_ID='Executando-notebook-etl' AIRFLOW_CTX_TASK_ID='transformando_dados' AIRFLOW_CTX_EXECUTION_DATE='2023-10-10T14:20:00+00:00' AIRFLOW_CTX_TRY_NUMBER='1' AIRFLOW_CTX_DAG_RUN_ID='scheduled__2023-10-10T14:20:00+00:00'
[2023-10-15T20:05:32.134-0300] {base.py:73} INFO - Using connection ID 'databricks_default' for task execution.
[2023-10-15T20:05:32.162-0300] {databricks_base.py:497} INFO - Using token auth.
[2023-10-15T20:05:32.777-0300] {databricks.py:54} INFO - Run submitted with run_id: 791943525403133
[2023-10-15T20:05:32.778-0300] {databricks_base.py:497} INFO - Using token auth.
[2023-10-15T20:05:33.107-0300] {process_utils.py:131} INFO - Sending Signals.SIGTERM to group 17397. PIDs of all processes in the group: [17397]
[2023-10-15T20:05:33.108-0300] {process_utils.py:86} INFO - Sending the signal Signals.SIGTERM to group 17397
[2023-10-15T20:05:33.108-0300] {taskinstance.py:1517} ERROR - Received SIGTERM. Terminating subprocesses.
[2023-10-15T20:05:33.109-0300] {databricks_base.py:497} INFO - Using token auth.
[2023-10-15T20:05:33.824-0300] {databricks.py:693} INFO - Task: transformando_dados with run_id: 791943525403133 was requested to be cancelled.
[2023-10-15T20:05:33.829-0300] {taskinstance.py:1824} ERROR - Task failed with exception
Traceback (most recent call last):
  File "/home/tinoco/airflow-databricks/curso_datAir/lib/python3.10/site-packages/airflow/providers/databricks/operators/databricks.py", line 684, in execute
    _handle_databricks_operator_execution(self, hook, self.log, context)
  File "/home/tinoco/airflow-databricks/curso_datAir/lib/python3.10/site-packages/airflow/providers/databricks/operators/databricks.py", line 55, in _handle_databricks_operator_execution
    run_page_url = hook.get_run_page_url(operator.run_id)
  File "/home/tinoco/airflow-databricks/curso_datAir/lib/python3.10/site-packages/airflow/providers/databricks/hooks/databricks.py", line 288, in get_run_page_url
    response = self._do_api_call(GET_RUN_ENDPOINT, json)
  File "/home/tinoco/airflow-databricks/curso_datAir/lib/python3.10/site-packages/airflow/providers/databricks/hooks/databricks_base.py", line 593, in _do_api_call
    for attempt in self._get_retry_object():
  File "/home/tinoco/airflow-databricks/curso_datAir/lib/python3.10/site-packages/tenacity/__init__.py", line 347, in __iter__
    do = self.iter(retry_state=retry_state)
  File "/home/tinoco/airflow-databricks/curso_datAir/lib/python3.10/site-packages/tenacity/__init__.py", line 314, in iter
    return fut.result()
  File "/usr/lib/python3.10/concurrent/futures/_base.py", line 451, in result
    return self.__get_result()
  File "/usr/lib/python3.10/concurrent/futures/_base.py", line 403, in __get_result
    raise self._exception
  File "/home/tinoco/airflow-databricks/curso_datAir/lib/python3.10/site-packages/airflow/providers/databricks/hooks/databricks_base.py", line 595, in _do_api_call
    response = request_func(
  File "/home/tinoco/airflow-databricks/curso_datAir/lib/python3.10/site-packages/requests/api.py", line 73, in get
    return request("get", url, params=params, **kwargs)
  File "/home/tinoco/airflow-databricks/curso_datAir/lib/python3.10/site-packages/requests/api.py", line 59, in request
    return session.request(method=method, url=url, **kwargs)
  File "/home/tinoco/airflow-databricks/curso_datAir/lib/python3.10/site-packages/requests/sessions.py", line 587, in request
    resp = self.send(prep, **send_kwargs)
  File "/home/tinoco/airflow-databricks/curso_datAir/lib/python3.10/site-packages/requests/sessions.py", line 701, in send
    r = adapter.send(request, **kwargs)
  File "/home/tinoco/airflow-databricks/curso_datAir/lib/python3.10/site-packages/requests/adapters.py", line 486, in send
    resp = conn.urlopen(
  File "/home/tinoco/airflow-databricks/curso_datAir/lib/python3.10/site-packages/urllib3/connectionpool.py", line 703, in urlopen
    httplib_response = self._make_request(
  File "/home/tinoco/airflow-databricks/curso_datAir/lib/python3.10/site-packages/urllib3/connectionpool.py", line 386, in _make_request
    self._validate_conn(conn)
  File "/home/tinoco/airflow-databricks/curso_datAir/lib/python3.10/site-packages/urllib3/connectionpool.py", line 1042, in _validate_conn
    conn.connect()
  File "/home/tinoco/airflow-databricks/curso_datAir/lib/python3.10/site-packages/urllib3/connection.py", line 419, in connect
    self.sock = ssl_wrap_socket(
  File "/home/tinoco/airflow-databricks/curso_datAir/lib/python3.10/site-packages/urllib3/util/ssl_.py", line 449, in ssl_wrap_socket
    ssl_sock = _ssl_wrap_socket_impl(
  File "/home/tinoco/airflow-databricks/curso_datAir/lib/python3.10/site-packages/urllib3/util/ssl_.py", line 493, in _ssl_wrap_socket_impl
    return ssl_context.wrap_socket(sock, server_hostname=server_hostname)
  File "/usr/lib/python3.10/ssl.py", line 513, in wrap_socket
    return self.sslsocket_class._create(
  File "/usr/lib/python3.10/ssl.py", line 1071, in _create
    self.do_handshake()
  File "/usr/lib/python3.10/ssl.py", line 1342, in do_handshake
    self._sslobj.do_handshake()
  File "/home/tinoco/airflow-databricks/curso_datAir/lib/python3.10/site-packages/airflow/models/taskinstance.py", line 1519, in signal_handler
    raise AirflowException("Task received SIGTERM signal")
airflow.exceptions.AirflowException: Task received SIGTERM signal
[2023-10-15T20:05:33.901-0300] {taskinstance.py:1345} INFO - Marking task as FAILED. dag_id=Executando-notebook-etl, task_id=transformando_dados, execution_date=20231010T142000, start_date=20231015T230531, end_date=20231015T230533
[2023-10-15T20:05:33.960-0300] {standard_task_runner.py:104} ERROR - Failed to execute job 289 for task transformando_dados (Task received SIGTERM signal; 17397)
[2023-10-15T20:05:34.004-0300] {process_utils.py:79} INFO - Process psutil.Process(pid=17397, status='terminated', exitcode=1, started='20:05:31') (17397) terminated with exit code 1
